Workbook
Name Baseline_Rate: Segment_Analysis!$F$4
Name FollowUp_Size: Lead_Scoring!$B$16
Name Hot_Cutoff: Lead_Scoring!$B$14
Name Profile_Inputs: Profile_Checker!$B$8:$B$15
Name Slicer_Education: #N/A
Name Slicer_Marital_Status: #N/A
Name Slicer_Region: #N/A
Name Takeaway_MinN: Pivot_Analysis!$F$4
Name Total_Buyers: Segment_Analysis!$D$4
Name Total_Customers: Segment_Analysis!$B$4
Name Warm_Cutoff: Lead_Scoring!$B$15

Sheet Dashboard
B1: Who Buys Bikes? Customer targeting dashboard | AA1: Chart data — do not edit
B3: 1,000 customers · purchase rate analysis · use the slicers to filter | AA3: % of Customers Targeted | AB3: Model | AC3: Random | AE3: Factor | AF3: Significant | AG3: Not significant
AA4: {=_xlfn.VSTACK(0,tbl_Gains[Decile]/ROWS(tbl_Gains[Decile]))} -> 0 | AB4: {=_xlfn.VSTACK(0,tbl_Gains[% of All Buyers Captured])} -> 0 | AC4: {=_xlfn.ANCHORARRAY(AA4)} -> 0 | AE4: {=_xlfn.LET(_xlpm.f,tbl_Significance[Factor],_xlpm.v,tbl_Significance[Cramér''s V],_xlpm.g,tbl_Significance[Significant?],_xlfn.SORTBY(_xlfn.HSTACK(_xlpm.f,IF(_xlpm.g="Yes",_xlpm.v,NA()),IF(_xlpm.g="No",_xlpm.v,NA())),_xlpm.v,1))} -> Home Owner | AF4: #N/A | AG4: 0.015153622
AA5: 0.1 | AB5: 0.16632017 | AC5: 0.1 | AE5: Gender | AF5: #N/A | AG5: 0.015178634
AA6: 0.2 | AB6: 0.3014553 | AC6: 0.2 | AE6: Occupation | AF6: #N/A | AG6: 0.089474532
AA7: 0.3 | AB7: 0.43866944 | AC7: 0.3 | AE7: Income Band | AF7: 0.10615007 | AG7: #N/A
AA8: 0.4 | AB8: 0.54677755 | AC8: 0.4 | AE8: Marital Status | AF8: 0.11151483 | AG8: #N/A
AA9: 0.5 | AB9: 0.65280665 | AC9: 0.5 | AE9: Region | AF9: 0.11727057 | AG9: #N/A
B10: Slicers filter the KPI cards and the four purchase-rate charts. Model charts show all customers. | AA10: 0.6 | AB10: 0.72557173 | AC10: 0.6 | AE10: Education | AF10: 0.15916245 | AG10: #N/A
B11: Customers | F11: Buyers | J11: Purchase rate | N11: Model · all customers | AA11: 0.7 | AB11: 0.80665281 | AC11: 0.7 | AE11: Children | AF11: 0.17903952 | AG11: #N/A
B12: =IFERROR(GETPIVOTDATA("Customers",Pivot_Analysis!$A$5),0) -> 1000 | F12: =IFERROR(GETPIVOTDATA("Buyers",Pivot_Analysis!$A$5),0) -> 481 | J12: =IFERROR(GETPIVOTDATA("Purchase Rate",Pivot_Analysis!$A$5),NA()) -> 0.481 | N12: =INDEX(tbl_TierSummary[Share of All Buyers],1) -> 0.43866944 | AA12: 0.8 | AB12: 0.91683992 | AC12: 0.8 | AE12: Commute Distance | AF12: 0.18577338 | AG12: #N/A
AA13: 0.9 | AB13: 0.96049896 | AC13: 0.9 | AE13: Age Band | AF13: 0.20549751 | AG13: #N/A
B14: ="of "&TEXT(Total_Customers,"#,##0")&" customers in total" -> of 1,000 customers in total | F14: =IFERROR(TEXT(F12/B12,"0.0%")&" of filtered customers bought","—") -> 48.1% of filtered customers bought | J14: =IFERROR(TEXT((J12-Baseline_Rate)*100,"+0.0;-0.0;0.0")&" pp vs "&TEXT(Baseline_Rate,"0.0%")&" overall","No customers in this filter") -> 0.0 pp vs 48.1% overall | N14: ="Hot tier's share of buyers (not filtered)" -> Hot tier's share of buyers (not filtered) | AA14: 1 | AB14: 1 | AC14: 1 | AE14: Car Ownership | AF14: 0.22331278 | AG14: #N/A
B15: =IF(B12<50,"⚠ Small group (n = "&TEXT(B12,"#,##0")&"). Read with caution.","") | AE15: Cars | AF15: 0.2257998 | AG15: #N/A
B16: Takeaways (these follow the slicers)
B17: {=IFERROR(_xlfn.LET(_xlpm.d,Pivot_Analysis!$A$12:$B$19,_xlpm.f,_xlfn._xlws.FILTER(_xlpm.d,ISNUMBER(INDEX(_xlpm.d,,2))),_xlpm.s,INDEX(_xlpm.f,,1),_xlpm.r,INDEX(_xlpm.f,,2),_xlpm.n,_xlfn.XLOOKUP(_xlpm.s,INDEX(Pivot_Analysis!$A$60:$B$67,,1),INDEX(Pivot_Analysis!$A$60:$B$67,,2),0),_xlpm.ok,_xlpm.n>=Takeaway_MinN,IF(SUM(--_xlpm.ok)=0,"• Best age band: not enough customers in any band to compare.",_xlfn.LET(_xlpm.rr,_xlfn._xlws.FILTER(_xlpm.r,_xlpm.ok),_xlpm.ss,_xlfn._xlws.FILTER(_xlpm.s,_xlpm.ok),_xlpm.nn,_xlfn._xlws.FILTER(_xlpm.n,_xlpm.ok),_xlpm.m,MAX(_xlpm.rr),"• Best age band: "&_xlfn.XLOOKUP(_xlpm.m,_xlpm.rr,_xlpm.ss)&" buys at "&TEXT(_xlpm.m,"0.0%")&" (n = "&TEXT(_xlfn.XLOOKUP(_xlpm.m,_xlpm.rr,_xlpm.nn),"#,##0")&")."))),"• Best age band: not enough customers in any band to compare.")} -> • Best age band: 31-40 buys at 61.1% (n = 316).
B18: =IFERROR(_xlfn.LET(_xlpm.na,IFERROR(GETPIVOTDATA("Customers",Pivot_Analysis!$A$79,"Car Ownership","0-1 Cars"),0),_xlpm.nb,IFERROR(GETPIVOTDATA("Customers",Pivot_Analysis!$A$79,"Car Ownership","2+ Cars"),0),IF(OR(_xlpm.na<Takeaway_MinN,_xlpm.nb<Takeaway_MinN),"• Car ownership gap: not enough customers in one group to compare.",_xlfn.LET(_xlpm.a,GETPIVOTDATA("Purchase Rate",Pivot_Analysis!$A$52,"Car Ownership","0-1 Cars"),_xlpm.b,GETPIVOTDATA("Purchase Rate",Pivot_Analysis!$A$52,"Car Ownership","2+ Cars"),"• Car ownership gap: 0-1 Cars buy at "&TEXT(_xlpm.a,"0.0%")&" vs "&TEXT(_xlpm.b,"0.0%")&" for 2+ Cars ("&TEXT((_xlpm.a-_xlpm.b)*100,"+0.0;-0.0;0.0")&" pp; n = "&TEXT(_xlpm.na,"#,##0")&" vs "&TEXT(_xlpm.nb,"#,##0")&")."))),"• Car ownership gap: not enough customers in one group to compare.") -> • Car ownership gap: 0-1 Cars buy at 58.9% vs 36.6% for 2+ Cars (+22.3 pp; n = 514 vs 486).
B19: {=IFERROR(_xlfn.LET(_xlpm.d,Pivot_Analysis!$A$22:$B$29,_xlpm.f,_xlfn._xlws.FILTER(_xlpm.d,ISNUMBER(INDEX(_xlpm.d,,2))),_xlpm.s,INDEX(_xlpm.f,,1),_xlpm.r,INDEX(_xlpm.f,,2),_xlpm.n,_xlfn.XLOOKUP(_xlpm.s,INDEX(Pivot_Analysis!$A$70:$B$77,,1),INDEX(Pivot_Analysis!$A$70:$B$77,,2),0),_xlpm.ok,_xlpm.n>=Takeaway_MinN,IF(SUM(--_xlpm.ok)=0,"• Lowest commute band: not enough customers in any band to compare.",_xlfn.LET(_xlpm.rr,_xlfn._xlws.FILTER(_xlpm.r,_xlpm.ok),_xlpm.ss,_xlfn._xlws.FILTER(_xlpm.s,_xlpm.ok),_xlpm.nn,_xlfn._xlws.FILTER(_xlpm.n,_xlpm.ok),_xlpm.m,MIN(_xlpm.rr),"• Lowest commute band: "&_xlfn.XLOOKUP(_xlpm.m,_xlpm.rr,_xlpm.ss)&" buys at only "&TEXT(_xlpm.m,"0.0%")&" (n = "&TEXT(_xlfn.XLOOKUP(_xlpm.m,_xlpm.rr,_xlpm.nn),"#,##0")&")."))),"• Lowest commute band: not enough customers in any band to compare.")} -> • Lowest commute band: 10+ Miles buys at only 29.7% (n = 111).
B72: Chart data for the model charts is in hidden columns AA–AI. See README_Brief › Technical notes.

Sheet README_Brief
A1: Who Buys Bikes? A Customer Targeting Analysis
A2: Purpose: project brief with the business question, approach and dataset, and a guide to every sheet in this workbook.
A4: Business question | B4: With a limited marketing budget, which customers should the retailer target to sell more bikes?
A5: Stakeholder | B5: Marketing Manager, bike retailer.
A6: Objective | B6: Find the groups most likely to buy, then score every customer so the best leads come first.
A7: Success metric | B7: Purchase rate = buyers ÷ customers (analysed by rate, not raw counts).
A8: Dataset | B8: Alex the Analyst's public Bike Buyers dataset. Raw: 1,026 rows × 13 fields, including 26 exact duplicate rows. After cleaning: 1,000 unique customers, 13 fields.
A9: Approach | B9: Clean → Segment by purchase rate → Test significance → Score leads → Dashboard → Recommendations.
A10: Tools | B10: Excel Tables, dynamic array formulas (LET, XLOOKUP, UNIQUE, FILTER, SORTBY), COUNTIFS, CHISQ.TEST, PivotTables, PivotCharts, slicers, GETPIVOTDATA, data validation, conditional formatting.
A11: Author | B11: Malachy Ugwu (github.com/Shikamaru-n)
A13: Sheet index
A14: Sheet | B14: Description
A15: Dashboard | B15: One-page summary: KPI cards, takeaways and four slicer-driven PivotCharts, plus two static model charts.
A16: README_Brief | B16: Project brief, approach, this sheet index and technical notes.
A17: Data_Dictionary | B17: Field definitions, data types, live unique-value counts and cleaning notes.
A18: Data_Quality_Log | B18: Log of every data issue found and the cleaning action taken, with live checks against Raw_Data.
A19: Clean_Data | B19: Clean dataset (tbl_Clean): 1,000 de-duplicated customers with decoded fields, plus 8 live formula columns (bands, sort keys, 1/0 purchase flag).
A20: Segment_Analysis | B20: Purchase rate and lift by every customer attribute and band, with a factor ranking by spread.
A21: Significance_Tests | B21: Chi-square tests (CHISQ.TEST) and Cramér's V showing which factors are significantly linked to purchasing.
A22: Lead_Scoring | B22: 0–100 propensity score, rank, decile and Hot/Warm/Cold tier for every customer, with tier summary and gains table.
A23: Profile_Checker | B23: Interactive dropdowns: pick a customer profile to see its estimated purchase rate, score, tier and matching customers.
A24: Pivot_Analysis | B24: Nine PivotTables. Six feed the Dashboard charts and KPI cards (KPIs, Age Band, Commute, Cars, Children, Car Ownership); three count segment sizes for the takeaways.
A25: Recommendations | B25: Seven actions for the Marketing Manager, each backed by a live number, plus limitations and next steps.
A26: Raw_Data | B26: Original source data (1,026 rows × 13 fields). Read-only and never modified.
A28: Technical notes
A29: # | B29: Where | C29: What | D29: Why
A30: 1 | B30: Dashboard, columns AA–AI (hidden) | C30: Chart data area for the two model charts: the gains table with "% of customers targeted", a random-targeting line and a 0% start point; Cramér's V split into "Significant" and "Not significant" columns, with #N/A where a factor doesn't belong. | D30: Ordinary charts must read from cells. Reshaping lets the gains curve compare the model with random targeting and lets bars be coloured by significance (#N/A draws no bar). Hidden to keep the dashboard clean; both charts are set to show data in hidden columns. Right-click the column headers → Unhide to inspect.
A31: 2 | B31: Clean_Data | C31: The 13 original columns are pasted values after de-duplication; the 8 derived columns are live formulas. | D31: An Excel Table can't hold a live UNIQUE() spill. Data_Quality_Log re-checks Clean_Data against Raw_Data with live formulas.
A32: 3 | B32: Pivot_Analysis | C32: Commute Distance order set manually (10+ Miles moved to the end). | D32: PivotTables sort text alphabetically, which would put 10+ before 2-5. A manual order persists on refresh.
A33: 4 | B33: Dashboard slicers | C33: Each slicer is connected to all 9 PivotTables via Report Connections. | D33: One click filters every PivotChart, KPI card and takeaway together.
A34: 5 | B34: Dashboard | C34: Slicers + PivotCharts for the filtered views; formula-based charts for the model results. | D34: Slicers can only drive PivotTables. Model results describe the whole customer base, so they stay fixed.
A35: 6 | B35: Profile_Checker | C35: Dropdowns (data validation) instead of slicers. | D35: The checker scores one hypothetical profile with formulas, which slicers can't drive.
A36: 7 | B36: Lead_Scoring | C36: Ties in Raw Score broken by lower ID; Decile = ROUNDUP(Rank × 10 / customers). | D36: Unique ranks give exactly 100 customers per decile.
A37: 8 | B37: Lead_Scoring | C37: Model uses 8 factors; excludes Cars (duplicates Car Ownership) and Occupation, Home Owner, Gender (not significant). | D37: Avoids double-counting and keeps only factors with statistical evidence (Significance_Tests).
A38: 9 | B38: Profile_Checker | C38: Scores outside the real customers' range are clamped to 0–100; likelihood uses the tier's actual purchase rate, not the decile's. | D38: Hypothetical profiles can be more extreme than any real customer; deciles 6 and 8 are uneven, tier rates are more stable.
A39: 10 | B39: Lead_Scoring / Profile_Checker | C39: Rates and scores are in-sample (built and evaluated on the same 1,000 customers). | D39: Results are indicative, not a validated forecast. See Recommendations.
A40: 11 | B40: Clean_Data and money cells | C40: Currency format [$$-en-US]#,##0. | D40: Prevents the en-NG locale displaying £.
A41: 12 | B41: Dashboard KPI cards | C41: Custom small-group warning: shows "⚠ Small group (n = X)" when filtered customers < 50. | D41: Percentages from small groups swing wildly (one customer can move the rate by 2+ pp); the threshold of 50 is a common rule of thumb, not an Excel feature.
... A43: 14 | B43: Pivot_Analysis E8:F12 | C43: Title cells for the 4 PivotCharts, linked to Baseline_Rate. | D43: PivotChart titles can only link to a cell, so these cells build "… (overall avg 48.1%)" and keep the average live.

Sheet Data_Dictionary
A1: Data dictionary
A2: Purpose: defines every Raw_Data field (type, meaning, examples and live unique-value count) and the cleaning it needs before analysis.
A4: Field | B4: Data Type | C4: Description | D4: Example Values | E4: Unique Values | F4: Notes/Cleaning Needed
A5: ID | B5: Whole number | C5: Unique customer identifier (primary key). | D5: 12496, 24107, 14177 | E5: =COUNTA(_xlfn.UNIQUE(_xlfn.XLOOKUP(tbl_Dictionary[[#This Row],[Field]],Raw_Data!$A$1:$M$1,Raw_Data!$A$2:$M$1027))) -> 1000 | F5: 26 exact duplicate rows (1,026 rows → 1,000 unique IDs). Remove duplicates in Clean_Data.
A6: Marital Status | B6: Text (code) | C6: Customer's marital status. | D6: M, S | E6: =COUNTA(_xlfn.UNIQUE(_xlfn.XLOOKUP(tbl_Dictionary[[#This Row],[Field]],Raw_Data!$A$1:$M$1,Raw_Data!$A$2:$M$1027))) -> 2 | F6: Recode M/S → Married/Single.
A7: Gender | B7: Text (code) | C7: Customer's gender. | D7: M, F | E7: =COUNTA(_xlfn.UNIQUE(_xlfn.XLOOKUP(tbl_Dictionary[[#This Row],[Field]],Raw_Data!$A$1:$M$1,Raw_Data!$A$2:$M$1027))) -> 2 | F7: Recode M/F → Male/Female.
A8: Income | B8: Number (US$) | C8: Annual household income in US dollars. | D8: $10,000 – $170,000 | E8: =COUNTA(_xlfn.UNIQUE(_xlfn.XLOOKUP(tbl_Dictionary[[#This Row],[Field]],Raw_Data!$A$1:$M$1,Raw_Data!$A$2:$M$1027))) -> 16 | F8: Recorded in $10,000 steps. Band into income groups for segmentation; display as [$$-en-US]#,##0.
A9: Children | B9: Whole number | C9: Number of children. | D9: 0 – 5 | E9: =COUNTA(_xlfn.UNIQUE(_xlfn.XLOOKUP(tbl_Dictionary[[#This Row],[Field]],Raw_Data!$A$1:$M$1,Raw_Data!$A$2:$M$1027))) -> 6 | F9: No cleaning needed.
A10: Education | B10: Text (category) | C10: Highest level of education completed. | D10: Partial High School, High School, Partial College, Bachelors, Graduate Degree | E10: =COUNTA(_xlfn.UNIQUE(_xlfn.XLOOKUP(tbl_Dictionary[[#This Row],[Field]],Raw_Data!$A$1:$M$1,Raw_Data!$A$2:$M$1027))) -> 5 | F10: Ordinal: needs an ordered sort (Partial High School → High School → Partial College → Bachelors → Graduate Degree), not alphabetical.
A11: Occupation | B11: Text (category) | C11: Occupation group. | D11: Manual, Skilled Manual, Clerical, Professional, Management | E11: =COUNTA(_xlfn.UNIQUE(_xlfn.XLOOKUP(tbl_Dictionary[[#This Row],[Field]],Raw_Data!$A$1:$M$1,Raw_Data!$A$2:$M$1027))) -> 5 | F11: No cleaning needed.
A12: Home Owner | B12: Text (Yes/No) | C12: Whether the customer owns their home. | D12: Yes, No | E12: =COUNTA(_xlfn.UNIQUE(_xlfn.XLOOKUP(tbl_Dictionary[[#This Row],[Field]],Raw_Data!$A$1:$M$1,Raw_Data!$A$2:$M$1027))) -> 2 | F12: No cleaning needed.
A13: Cars | B13: Whole number | C13: Number of cars owned. | D13: 0 – 4 | E13: =COUNTA(_xlfn.UNIQUE(_xlfn.XLOOKUP(tbl_Dictionary[[#This Row],[Field]],Raw_Data!$A$1:$M$1,Raw_Data!$A$2:$M$1027))) -> 5 | F13: No cleaning needed.
A14: Commute Distance | B14: Text (category) | C14: Distance from home to work. | D14: 0-1 Miles, 1-2 Miles, 2-5 Miles, 5-10 Miles, 10+ Miles | E14: =COUNTA(_xlfn.UNIQUE(_xlfn.XLOOKUP(tbl_Dictionary[[#This Row],[Field]],Raw_Data!$A$1:$M$1,Raw_Data!$A$2:$M$1027))) -> 5 | F14: Ordinal: needs a sort order (0-1, 1-2, 2-5, 5-10, 10+). Alphabetical sorting puts 10+ second.
A15: Region | B15: Text (category) | C15: Geographic region. | D15: Europe, North America, Pacific | E15: =COUNTA(_xlfn.UNIQUE(_xlfn.XLOOKUP(tbl_Dictionary[[#This Row],[Field]],Raw_Data!$A$1:$M$1,Raw_Data!$A$2:$M$1027))) -> 3 | F15: No cleaning needed.
A16: Age | B16: Whole number | C16: Customer's age in years. | D16: 25 – 89 | E16: =COUNTA(_xlfn.UNIQUE(_xlfn.XLOOKUP(tbl_Dictionary[[#This Row],[Field]],Raw_Data!$A$1:$M$1,Raw_Data!$A$2:$M$1027))) -> 53 | F16: Too many distinct values to segment directly. Band into age groups.
A17: Purchased Bike | B17: Text (Yes/No) | C17: Whether the customer bought a bike. | D17: Yes, No | E17: =COUNTA(_xlfn.UNIQUE(_xlfn.XLOOKUP(tbl_Dictionary[[#This Row],[Field]],Raw_Data!$A$1:$M$1,Raw_Data!$A$2:$M$1027))) -> 2 | F17: Target variable. Convert to a 1/0 flag in Clean_Data so purchase rate = AVERAGE(flag).
A19: Live data checks (against Raw_Data)
A20: Total rows | B20: =ROWS(Raw_Data!$A$2:$A$1027) -> 1026 | C20: Raw dataset size.
A21: Unique IDs | B21: =COUNTA(_xlfn.UNIQUE(Raw_Data!$A$2:$A$1027)) -> 1000 | C21: Unique customers after de-duplication.
A22: Exact duplicate rows | B22: =ROWS(Raw_Data!$A$2:$M$1027)-ROWS(_xlfn.UNIQUE(Raw_Data!$A$2:$M$1027)) -> 26 | C22: To be removed in Clean_Data.
A23: Blank cells (all 13 fields) | B23: =COUNTBLANK(Raw_Data!$A$2:$M$1027) -> 0 | C23: No blank values in any field, so no imputation is needed.

Sheet Data_Quality_Log
A1: Data quality log
A2: Purpose: audit trail of every data-quality check and cleaning action from Raw_Data to Clean_Data, with live validation checks.
A4: Step | B4: Check / Action | C4: Field(s) | D4: Rows Before | E4: Rows Affected | F4: Rows After | G4: Method | H4: Rationale
A5: 1 | B5: Row count check (Raw_Data) | C5: All 13 fields | D5: =ROWS(Raw_Data!$A$2:$A$1027) -> 1026 | E5: 0 | F5: =D5-E5 -> 1026 | G5: ROWS() on Raw_Data. | H5: Establish the baseline row count before any cleaning.
A6: 2 | B6: Blank value check (all 13 fields) | C6: All 13 fields | D6: =ROWS(Raw_Data!$A$2:$A$1027) -> 1026 | E6: =COUNTBLANK(Raw_Data!$A$2:$M$1027) -> 0 | F6: =ROWS(Raw_Data!$A$2:$A$1027) -> 1026 | G6: COUNTBLANK() across Raw_Data!A2:M1027 (Rows Affected = blank cells found). | H6: Blanks would bias purchase rates; none found, so no imputation or exclusion needed.
A7: 3 | B7: Exact duplicate removal | C7: All 13 fields | D7: =ROWS(Raw_Data!$A$2:$A$1027) -> 1026 | E7: =ROWS(Raw_Data!$A$2:$A$1027)-ROWS(_xlfn.UNIQUE(Raw_Data!$A$2:$M$1027)) -> 26 | F7: =ROWS(tbl_Clean[]) -> 1000 | G7: Copied Raw_Data to Clean_Data and removed rows identical across all 13 fields, keeping the first occurrence in original order. | H7: Duplicate customers would be double-counted and inflate segment counts and rates.
A8: 4 | B8: Duplicate ID check after removal | C8: ID | D8: =ROWS(tbl_Clean[ID]) -> 1000 | E8: =ROWS(tbl_Clean[ID])-ROWS(_xlfn.UNIQUE(tbl_Clean[ID])) -> 0 | F8: =D8-E8 -> 1000 | G8: ROWS() minus ROWS(UNIQUE()) on tbl_Clean[ID]. | H8: Confirms ID is a true primary key: one row per customer.
A9: 5 | B9: Range check: Age (25-89), Income ($10k-$170k), Children (0-5), Cars (0-4) | C9: Age, Income, Children, Cars | D9: =ROWS(tbl_Clean[]) -> 1000 | E9: {=SUM(COUNTIFS(tbl_Clean[Age],{"<25",">89"}),COUNTIFS(tbl_Clean[Income],{"<10000",">170000"}),COUNTIFS(tbl_Clean[Children],{"<0",">5"}),COUNTIFS(tbl_Clean[Cars],{"<0",">4"}))} -> 0 | F9: =D9-E9 -> 1000 | G9: COUNTIFS() for values outside each expected range (Rows Affected = out-of-range values). | H9: Catches impossible or mistyped values that would distort the bands.
A10: 6 | B10: Category consistency check (no typos / stray spaces in text fields) | C10: Marital Status, Gender, Education, Occupation, Home Owner, Commute Distance, Region, Purchased Bike | D10: =ROWS(tbl_Clean[]) -> 1000 | E10: {=SUMPRODUCT(--(LEN(tbl_Clean[[Marital Status]:[Purchased Bike]])<>LEN(TRIM(tbl_Clean[[Marital Status]:[Purchased Bike]]))))} -> 0 | F10: =D10-E10 -> 1000 | G10: LEN() vs LEN(TRIM()) for stray spaces (Rows Affected = cells with stray spaces). UNIQUE() level counts were reviewed against Data_Dictionary and showed no unexpected variants. | H10: Typos or trailing spaces would split one category into several and fragment segment rates.
A11: 7 | B11: Decode Marital Status and Gender | C11: Marital Status, Gender | D11: =ROWS(tbl_Clean[]) -> 1000 | E11: {=SUM(COUNTIFS(tbl_Clean[Marital Status],{"Married","Single"}))} -> 1000 | F11: =ROWS(tbl_Clean[]) -> 1000 | G11: Recoded in place in Clean_Data: M→Married, S→Single; M→Male, F→Female (Rows Affected = rows decoded). | H11: Readable labels for charts and slicers. It also removes the clash between M (Married) and M (Male).
A12: 8 | B12: Derived columns added: Age Band, Age Band Sort, Income Band, Income Band Sort, Car Ownership, Commute Sort, Education Sort, Purchased Flag | C12: Age, Income, Cars, Commute Distance, Education, Purchased Bike | D12: =ROWS(tbl_Clean[]) -> 1000 | E12: =ROWS(tbl_Clean[]) -> 1000 | F12: =ROWS(tbl_Clean[]) -> 1000 | G12: Live structured-reference formulas in tbl_Clean (IFS for bands, XMATCH for sort orders, IF for the 1/0 flag). | H12: Bands make continuous fields segmentable; sort keys give a logical (not alphabetical) order; the flag lets purchase rate = AVERAGE(flag).
B14: Validation checks
B15: Check | C15: Expected | D15: Actual | E15: Status
B16: Clean rows = 1,000 | C16: 1000 | D16: =ROWS(tbl_Clean[]) -> 1000 | E16: =IF(tbl_Validation[[#This Row],[Actual]]=tbl_Validation[[#This Row],[Expected]],"PASS","FAIL") -> PASS
B17: Unique IDs in tbl_Clean = 1,000 | C17: 1000 | D17: =ROWS(_xlfn.UNIQUE(tbl_Clean[ID])) -> 1000 | E17: =IF(tbl_Validation[[#This Row],[Actual]]=tbl_Validation[[#This Row],[Expected]],"PASS","FAIL") -> PASS
B18: Blank cells in tbl_Clean = 0 | C18: 0 | D18: =COUNTBLANK(tbl_Clean[]) -> 0 | E18: =IF(tbl_Validation[[#This Row],[Actual]]=tbl_Validation[[#This Row],[Expected]],"PASS","FAIL") -> PASS
B19: Raw unique rows = Clean rows | C19: =ROWS(_xlfn.UNIQUE(Raw_Data!$A$2:$M$1027)) -> 1000 | D19: =ROWS(tbl_Clean[]) -> 1000 | E19: =IF(tbl_Validation[[#This Row],[Actual]]=tbl_Validation[[#This Row],[Expected]],"PASS","FAIL") -> PASS
B20: Sum of Purchased Flag = count of "Yes" in tbl_Clean | C20: =COUNTIFS(tbl_Clean[Purchased Bike],"Yes") -> 481 | D20: =SUM(tbl_Clean[Purchased Flag]) -> 481 | E20: =IF(tbl_Validation[[#This Row],[Actual]]=tbl_Validation[[#This Row],[Expected]],"PASS","FAIL") -> PASS
B21: Only Married/Single and Male/Female in Marital Status and Gender (invalid values = 0) | C21: 0 | D21: {=2*ROWS(tbl_Clean[])-SUM(COUNTIFS(tbl_Clean[Marital Status],{"Married","Single"}))-SUM(COUNTIFS(tbl_Clean[Gender],{"Male","Female"}))} -> 0 | E21: =IF(tbl_Validation[[#This Row],[Actual]]=tbl_Validation[[#This Row],[Expected]],"PASS","FAIL") -> PASS
B22: Every row has a non-blank Age Band and Income Band (missing = 0) | C22: 0 | D22: =2*ROWS(tbl_Clean[])-COUNTIF(tbl_Clean[Age Band],"?*")-COUNTIF(tbl_Clean[Income Band],"?*") -> 0 | E22: =IF(tbl_Validation[[#This Row],[Actual]]=tbl_Validation[[#This Row],[Expected]],"PASS","FAIL") -> PASS
B24: Overall data quality: | C24: =IF(COUNTIF(tbl_Validation[Status],"FAIL")=0,"ALL CHECKS PASSED",COUNTIF(tbl_Validation[Status],"FAIL")&" CHECK(S) FAILED") -> ALL CHECKS PASSED

Sheet Clean_Data
A1: Clean data
A2: Purpose: analysis-ready dataset of 1,000 unique customers (26 exact duplicates removed), with codes decoded and live band, sort and flag columns.
A4: ID | B4: Marital Status | C4: Gender | D4: Income | E4: Children | F4: Education | G4: Occupation | H4: Home Owner | I4: Cars | J4: Commute Distance | K4: Region | L4: Age | M4: Purchased Bike | N4: Age Band | O4: Age Band Sort | P4: Income Band | Q4: Income Band Sort | R4: Car Ownership | S4: Commute Sort | T4: Education Sort | U4: Purchased Flag
A5: 12496 | B5: Married | C5: Female | D5: 40000 | E5: 1 | F5: Bachelors | G5: Skilled Manual | H5: Yes | I5: 0 | J5: 0-1 Miles | K5: Europe | L5: 42 | M5: No | N5: {=_xlfn.IFS(tbl_Clean[[#This Row],[Age]]<=30,"25-30",tbl_Clean[[#This Row],[Age]]<=40,"31-40",tbl_Clean[[#This Row],[Age]]<=50,"41-50",tbl_Clean[[#This Row],[Age]]<=60,"51-60",TRUE,"61+")} -> 41-50 | O5: =_xlfn.XMATCH(tbl_Clean[[#This Row],[Age Band]],{"25-30","31-40","41-50","51-60","61+"}) -> 3 | P5: {=_xlfn.IFS(tbl_Clean[[#This Row],[Income]]<=30000,"$10k-30k",tbl_Clean[[#This Row],[Income]]<=60000,"$40k-60k",tbl_Clean[[#This Row],[Income]]<=90000,"$70k-90k",TRUE,"$100k+")} -> $40k-60k | Q5: =_xlfn.XMATCH(tbl_Clean[[#This Row],[Income Band]],{"$10k-30k","$40k-60k","$70k-90k","$100k+"}) -> 2 | R5: =IF(tbl_Clean[[#This Row],[Cars]]<=1,"0-1 Cars","2+ Cars") -> 0-1 Cars | S5: =_xlfn.XMATCH(tbl_Clean[[#This Row],[Commute Distance]],{"0-1 Miles","1-2 Miles","2-5 Miles","5-10 Miles","10+ Miles"}) -> 1 | T5: =_xlfn.XMATCH(tbl_Clean[[#This Row],[Education]],{"Partial High School","High School","Partial College","Bachelors","Graduate Degree"}) -> 4 | U5: =IF(tbl_Clean[[#This Row],[Purchased Bike]]="Yes",1,0) -> 0
A6: 24107 | B6: Married | C6: Male | D6: 30000 | E6: 3 | F6: Partial College | G6: Clerical | H6: Yes | I6: 1 | J6: 0-1 Miles | K6: Europe | L6: 43 | M6: No | N6: {=_xlfn.IFS(tbl_Clean[[#This Row],[Age]]<=30,"25-30",tbl_Clean[[#This Row],[Age]]<=40,"31-40",tbl_Clean[[#This Row],[Age]]<=50,"41-50",tbl_Clean[[#This Row],[Age]]<=60,"51-60",TRUE,"61+")} -> 41-50 | O6: =_xlfn.XMATCH(tbl_Clean[[#This Row],[Age Band]],{"25-30","31-40","41-50","51-60","61+"}) -> 3 | P6: {=_xlfn.IFS(tbl_Clean[[#This Row],[Income]]<=30000,"$10k-30k",tbl_Clean[[#This Row],[Income]]<=60000,"$40k-60k",tbl_Clean[[#This Row],[Income]]<=90000,"$70k-90k",TRUE,"$100k+")} -> $10k-30k | Q6: =_xlfn.XMATCH(tbl_Clean[[#This Row],[Income Band]],{"$10k-30k","$40k-60k","$70k-90k","$100k+"}) -> 1 | R6: =IF(tbl_Clean[[#This Row],[Cars]]<=1,"0-1 Cars","2+ Cars") -> 0-1 Cars | S6: =_xlfn.XMATCH(tbl_Clean[[#This Row],[Commute Distance]],{"0-1 Miles","1-2 Miles","2-5 Miles","5-10 Miles","10+ Miles"}) -> 1 | T6: =_xlfn.XMATCH(tbl_Clean[[#This Row],[Education]],{"Partial High School","High School","Partial College","Bachelors","Graduate Degree"}) -> 3 | U6: =IF(tbl_Clean[[#This Row],[Purchased Bike]]="Yes",1,0) -> 0
A7: 14177 | B7: Married | C7: Male | D7: 80000 | E7: 5 | F7: Partial College | G7: Professional | H7: No | I7: 2 | J7: 2-5 Miles | K7: Europe | L7: 60 | M7: No | N7: {=_xlfn.IFS(tbl_Clean[[#This Row],[Age]]<=30,"25-30",tbl_Clean[[#This Row],[Age]]<=40,"31-40",tbl_Clean[[#This Row],[Age]]<=50,"41-50",tbl_Clean[[#This Row],[Age]]<=60,"51-60",TRUE,"61+")} -> 51-60 | O7: =_xlfn.XMATCH(tbl_Clean[[#This Row],[Age Band]],{"25-30","31-40","41-50","51-60","61+"}) -> 4 | P7: {=_xlfn.IFS(tbl_Clean[[#This Row],[Income]]<=30000,"$10k-30k",tbl_Clean[[#This Row],[Income]]<=60000,"$40k-60k",tbl_Clean[[#This Row],[Income]]<=90000,"$70k-90k",TRUE,"$100k+")} -> $70k-90k | Q7: =_xlfn.XMATCH(tbl_Clean[[#This Row],[Income Band]],{"$10k-30k","$40k-60k","$70k-90k","$100k+"}) -> 3 | R7: =IF(tbl_Clean[[#This Row],[Cars]]<=1,"0-1 Cars","2+ Cars") -> 2+ Cars | S7: =_xlfn.XMATCH(tbl_Clean[[#This Row],[Commute Distance]],{"0-1 Miles","1-2 Miles","2-5 Miles","5-10 Miles","10+ Miles"}) -> 3 | T7: =_xlfn.XMATCH(tbl_Clean[[#This Row],[Education]],{"Partial High School","High School","Partial College","Bachelors","Graduate Degree"}) -> 3 | U7: =IF(tbl_Clean[[#This Row],[Purchased Bike]]="Yes",1,0) -> 0
A8: 24381 | B8: Single | C8: Male | D8: 70000 | E8: 0 | F8: Bachelors | G8: Professional | H8: Yes | I8: 1 | J8: 5-10 Miles | K8: Pacific | L8: 41 | M8: Yes | N8: {=_xlfn.IFS(tbl_Clean[[#This Row],[Age]]<=30,"25-30",tbl_Clean[[#This Row],[Age]]<=40,"31-40",tbl_Clean[[#This Row],[Age]]<=50,"41-50",tbl_Clean[[#This Row],[Age]]<=60,"51-60",TRUE,"61+")} -> 41-50 | O8: =_xlfn.XMATCH(tbl_Clean[[#This Row],[Age Band]],{"25-30","31-40","41-50","51-60","61+"}) -> 3 | P8: {=_xlfn.IFS(tbl_Clean[[#This Row],[Income]]<=30000,"$10k-30k",tbl_Clean[[#This Row],[Income]]<=60000,"$40k-60k",tbl_Clean[[#This Row],[Income]]<=90000,"$70k-90k",TRUE,"$100k+")} -> $70k-90k | Q8: =_xlfn.XMATCH(tbl_Clean[[#This Row],[Income Band]],{"$10k-30k","$40k-60k","$70k-90k","$100k+"}) -> 3 | R8: =IF(tbl_Clean[[#This Row],[Cars]]<=1,"0-1 Cars","2+ Cars") -> 0-1 Cars | S8: =_xlfn.XMATCH(tbl_Clean[[#This Row],[Commute Distance]],{"0-1 Miles","1-2 Miles","2-5 Miles","5-10 Miles","10+ Miles"}) -> 4 | T8: =_xlfn.XMATCH(tbl_Clean[[#This Row],[Education]],{"Partial High School","High School","Partial College","Bachelors","Graduate Degree"}) -> 4 | U8: =IF(tbl_Clean[[#This Row],[Purchased Bike]]="Yes",1,0) -> 1
A9: 25597 | B9: Single | C9: Male | D9: 30000 | E9: 0 | F9: Bachelors | G9: Clerical | H9: No | I9: 0 | J9: 0-1 Miles | K9: Europe | L9: 36 | M9: Yes | N9: {=_xlfn.IFS(tbl_Clean[[#This Row],[Age]]<=30,"25-30",tbl_Clean[[#This Row],[Age]]<=40,"31-40",tbl_Clean[[#This Row],[Age]]<=50,"41-50",tbl_Clean[[#This Row],[Age]]<=60,"51-60",TRUE,"61+")} -> 31-40 | O9: =_xlfn.XMATCH(tbl_Clean[[#This Row],[Age Band]],{"25-30","31-40","41-50","51-60","61+"}) -> 2 | P9: {=_xlfn.IFS(tbl_Clean[[#This Row],[Income]]<=30000,"$10k-30k",tbl_Clean[[#This Row],[Income]]<=60000,"$40k-60k",tbl_Clean[[#This Row],[Income]]<=90000,"$70k-90k",TRUE,"$100k+")} -> $10k-30k | Q9: =_xlfn.XMATCH(tbl_Clean[[#This Row],[Income Band]],{"$10k-30k","$40k-60k","$70k-90k","$100k+"}) -> 1 | R9: =IF(tbl_Clean[[#This Row],[Cars]]<=1,"0-1 Cars","2+ Cars") -> 0-1 Cars | S9: =_xlfn.XMATCH(tbl_Clean[[#This Row],[Commute Distance]],{"0-1 Miles","1-2 Miles","2-5 Miles","5-10 Miles","10+ Miles"}) -> 1 | T9: =_xlfn.XMATCH(tbl_Clean[[#This Row],[Education]],{"Partial High School","High School","Partial College","Bachelors","Graduate Degree"}) -> 4 | U9: =IF(tbl_Clean[[#This Row],[Purchased Bike]]="Yes",1,0) -> 1
A10: 13507 | B10: Married | C10: Female | D10: 10000 | E10: 2 | F10: Partial College | G10: Manual | H10: Yes | I10: 0 | J10: 1-2 Miles | K10: Europe | L10: 50 | M10: No | N10: {=_xlfn.IFS(tbl_Clean[[#This Row],[Age]]<=30,"25-30",tbl_Clean[[#This Row],[Age]]<=40,"31-40",tbl_Clean[[#This Row],[Age]]<=50,"41-50",tbl_Clean[[#This Row],[Age]]<=60,"51-60",TRUE,"61+")} -> 41-50 | O10: =_xlfn.XMATCH(tbl_Clean[[#This Row],[Age Band]],{"25-30","31-40","41-50","51-60","61+"}) -> 3 | P10: {=_xlfn.IFS(tbl_Clean[[#This Row],[Income]]<=30000,"$10k-30k",tbl_Clean[[#This Row],[Income]]<=60000,"$40k-60k",tbl_Clean[[#This Row],[Income]]<=90000,"$70k-90k",TRUE,"$100k+")} -> $10k-30k | Q10: =_xlfn.XMATCH(tbl_Clean[[#This Row],[Income Band]],{"$10k-30k","$40k-60k","$70k-90k","$100k+"}) -> 1 | R10: =IF(tbl_Clean[[#This Row],[Cars]]<=1,"0-1 Cars","2+ Cars") -> 0-1 Cars | S10: =_xlfn.XMATCH(tbl_Clean[[#This Row],[Commute Distance]],{"0-1 Miles","1-2 Miles","2-5 Miles","5-10 Miles","10+ Miles"}) -> 2 | T10: =_xlfn.XMATCH(tbl_Clean[[#This Row],[Education]],{"Partial High School","High School","Partial College","Bachelors","Graduate Degree"}) -> 3 | U10: =IF(tbl_Clean[[#This Row],[Purchased Bike]]="Yes",1,0) -> 0
A11: 27974 | B11: Single | C11: Male | D11: 160000 | E11: 2 | F11: High School | G11: Management | H11: Yes | I11: 4 | J11: 0-1 Miles | K11: Pacific | L11: 33 | M11: Yes | N11: {=_xlfn.IFS(tbl_Clean[[#This Row],[Age]]<=30,"25-30",tbl_Clean[[#This Row],[Age]]<=40,"31-40",tbl_Clean[[#This Row],[Age]]<=50,"41-50",tbl_Clean[[#This Row],[Age]]<=60,"51-60",TRUE,"61+")} -> 31-40 | O11: =_xlfn.XMATCH(tbl_Clean[[#This Row],[Age Band]],{"25-30","31-40","41-50","51-60","61+"}) -> 2 | P11: {=_xlfn.IFS(tbl_Clean[[#This Row],[Income]]<=30000,"$10k-30k",tbl_Clean[[#This Row],[Income]]<=60000,"$40k-60k",tbl_Clean[[#This Row],[Income]]<=90000,"$70k-90k",TRUE,"$100k+")} -> $100k+ | Q11: =_xlfn.XMATCH(tbl_Clean[[#This Row],[Income Band]],{"$10k-30k","$40k-60k","$70k-90k","$100k+"}) -> 4 | R11: =IF(tbl_Clean[[#This Row],[Cars]]<=1,"0-1 Cars","2+ Cars") -> 2+ Cars | S11: =_xlfn.XMATCH(tbl_Clean[[#This Row],[Commute Distance]],{"0-1 Miles","1-2 Miles","2-5 Miles","5-10 Miles","10+ Miles"}) -> 1 | T11: =_xlfn.XMATCH(tbl_Clean[[#This Row],[Education]],{"Partial High School","High School","Partial College","Bachelors","Graduate Degree"}) -> 2 | U11: =IF(tbl_Clean[[#This Row],[Purchased Bike]]="Yes",1,0) -> 1
A12: 19364 | B12: Married | C12: Male | D12: 40000 | E12: 1 | F12: Bachelors | G12: Skilled Manual | H12: Yes | I12: 0 | J12: 0-1 Miles | K12: Europe | L12: 43 | M12: Yes | N12: {=_xlfn.IFS(tbl_Clean[[#This Row],[Age]]<=30,"25-30",tbl_Clean[[#This Row],[Age]]<=40,"31-40",tbl_Clean[[#This Row],[Age]]<=50,"41-50",tbl_Clean[[#This Row],[Age]]<=60,"51-60",TRUE,"61+")} -> 41-50 | O12: =_xlfn.XMATCH(tbl_Clean[[#This Row],[Age Band]],{"25-30","31-40","41-50","51-60","61+"}) -> 3 | P12: {=_xlfn.IFS(tbl_Clean[[#This Row],[Income]]<=30000,"$10k-30k",tbl_Clean[[#This Row],[Income]]<=60000,"$40k-60k",tbl_Clean[[#This Row],[Income]]<=90000,"$70k-90k",TRUE,"$100k+")} -> $40k-60k | Q12: =_xlfn.XMATCH(tbl_Clean[[#This Row],[Income Band]],{"$10k-30k","$40k-60k","$70k-90k","$100k+"}) -> 2 | R12: =IF(tbl_Clean[[#This Row],[Cars]]<=1,"0-1 Cars","2+ Cars") -> 0-1 Cars | S12: =_xlfn.XMATCH(tbl_Clean[[#This Row],[Commute Distance]],{"0-1 Miles","1-2 Miles","2-5 Miles","5-10 Miles","10+ Miles"}) -> 1 | T12: =_xlfn.XMATCH(tbl_Clean[[#This Row],[Education]],{"Partial High School","High School","Partial College","Bachelors","Graduate Degree"}) -> 4 | U12: =IF(tbl_Clean[[#This Row],[Purchased Bike]]="Yes",1,0) -> 1
A13: 22155 | B13: Married | C13: Male | D13: 20000 | E13: 2 | F13: Partial High School | G13: Clerical | H13: Yes | I13: 2 | J13: 5-10 Miles | K13: Pacific | L13: 58 | M13: No | N13: {=_xlfn.IFS(tbl_Clean[[#This Row],[Age]]<=30,"25-30",tbl_Clean[[#This Row],[Age]]<=40,"31-40",tbl_Clean[[#This Row],[Age]]<=50,"41-50",tbl_Clean[[#This Row],[Age]]<=60,"51-60",TRUE,"61+")} -> 51-60 | O13: =_xlfn.XMATCH(tbl_Clean[[#This Row],[Age Band]],{"25-30","31-40","41-50","51-60","61+"}) -> 4 | P13: {=_xlfn.IFS(tbl_Clean[[#This Row],[Income]]<=30000,"$10k-30k",tbl_Clean[[#This Row],[Income]]<=60000,"$40k-60k",tbl_Clean[[#This Row],[Income]]<=90000,"$70k-90k",TRUE,"$100k+")} -> $10k-30k | Q13: =_xlfn.XMATCH(tbl_Clean[[#This Row],[Income Band]],{"$10k-30k","$40k-60k","$70k-90k","$100k+"}) -> 1 | R13: =IF(tbl_Clean[[#This Row],[Cars]]<=1,"0-1 Cars","2+ Cars") -> 2+ Cars | S13: =_xlfn.XMATCH(tbl_Clean[[#This Row],[Commute Distance]],{"0-1 Miles","1-2 Miles","2-5 Miles","5-10 Miles","10+ Miles"}) -> 4 | T13: =_xlfn.XMATCH(tbl_Clean[[#This Row],[Education]],{"Partial High School","High School","Partial College","Bachelors","Graduate Degree"}) -> 1 | U13: =IF(tbl_Clean[[#This Row],[Purchased Bike]]="Yes",1,0) -> 0
A14: 19280 | B14: Married | C14: Male | D14: 120000 | E14: 2 | F14: Partial College | G14: Manual | H14: Yes | I14: 1 | J14: 0-1 Miles | K14: Europe | L14: 40 | M14: Yes | N14: {=_xlfn.IFS(tbl_Clean[[#This Row],[Age]]<=30,"25-30",tbl_Clean[[#This Row],[Age]]<=40,"31-40",tbl_Clean[[#This Row],[Age]]<=50,"41-50",tbl_Clean[[#This Row],[Age]]<=60,"51-60",TRUE,"61+")} -> 31-40 | O14: =_xlfn.XMATCH(tbl_Clean[[#This Row],[Age Band]],{"25-30","31-40","41-50","51-60","61+"}) -> 2 | P14: {=_xlfn.IFS(tbl_Clean[[#This Row],[Income]]<=30000,"$10k-30k",tbl_Clean[[#This Row],[Income]]<=60000,"$40k-60k",tbl_Clean[[#This Row],[Income]]<=90000,"$70k-90k",TRUE,"$100k+")} -> $100k+ | Q14: =_xlfn.XMATCH(tbl_Clean[[#This Row],[Income Band]],{"$10k-30k","$40k-60k","$70k-90k","$100k+"}) -> 4 | R14: =IF(tbl_Clean[[#This Row],[Cars]]<=1,"0-1 Cars","2+ Cars") -> 0-1 Cars | S14: =_xlfn.XMATCH(tbl_Clean[[#This Row],[Commute Distance]],{"0-1 Miles","1-2 Miles","2-5 Miles","5-10 Miles","10+ Miles"}) -> 1 | T14: =_xlfn.XMATCH(tbl_Clean[[#This Row],[Education]],{"Partial High School","High School","Partial College","Bachelors","Graduate Degree"}) -> 3 | U14: =IF(tbl_Clean[[#This Row],[Purchased Bike]]="Yes",1,0) -> 1
A15: 22173 | B15: Married | C15: Female | D15: 30000 | E15: 3 | F15: High School | G15: Skilled Manual | H15: No | I15: 2 | J15: 1-2 Miles | K15: Pacific | L15: 54 | M15: Yes | N15: {=_xlfn.IFS(tbl_Clean[[#This Row],[Age]]<=30,"25-30",tbl_Clean[[#This Row],[Age]]<=40,"31-40",tbl_Clean[[#This Row],[Age]]<=50,"41-50",tbl_Clean[[#This Row],[Age]]<=60,"51-60",TRUE,"61+")} -> 51-60 | O15: =_xlfn.XMATCH(tbl_Clean[[#This Row],[Age Band]],{"25-30","31-40","41-50","51-60","61+"}) -> 4 | P15: {=_xlfn.IFS(tbl_Clean[[#This Row],[Income]]<=30000,"$10k-30k",tbl_Clean[[#This Row],[Income]]<=60000,"$40k-60k",tbl_Clean[[#This Row],[Income]]<=90000,"$70k-90k",TRUE,"$100k+")} -> $10k-30k | Q15: =_xlfn.XMATCH(tbl_Clean[[#This Row],[Income Band]],{"$10k-30k","$40k-60k","$70k-90k","$100k+"}) -> 1 | R15: =IF(tbl_Clean[[#This Row],[Cars]]<=1,"0-1 Cars","2+ Cars") -> 2+ Cars | S15: =_xlfn.XMATCH(tbl_Clean[[#This Row],[Commute Distance]],{"0-1 Miles","1-2 Miles","2-5 Miles","5-10 Miles","10+ Miles"}) -> 2 | T15: =_xlfn.XMATCH(tbl_Clean[[#This Row],[Education]],{"Partial High School","High School","Partial College","Bachelors","Graduate Degree"}) -> 2 | U15: =IF(tbl_Clean[[#This Row],[Purchased Bike]]="Yes",1,0) -> 1
A16: 12697 | B16: Single | C16: Female | D16: 90000 | E16: 0 | F16: Bachelors | G16: Professional | H16: No | I16: 4 | J16: 10+ Miles | K16: Pacific | L16: 36 | M16: No | N16: {=_xlfn.IFS(tbl_Clean[[#This Row],[Age]]<=30,"25-30",tbl_Clean[[#This Row],[Age]]<=40,"31-40",tbl_Clean[[#This Row],[Age]]<=50,"41-50",tbl_Clean[[#This Row],[Age]]<=60,"51-60",TRUE,"61+")} -> 31-40 | O16: =_xlfn.XMATCH(tbl_Clean[[#This Row],[Age Band]],{"25-30","31-40","41-50","51-60","61+"}) -> 2 | P16: {=_xlfn.IFS(tbl_Clean[[#This Row],[Income]]<=30000,"$10k-30k",tbl_Clean[[#This Row],[Income]]<=60000,"$40k-60k",tbl_Clean[[#This Row],[Income]]<=90000,"$70k-90k",TRUE,"$100k+")} -> $70k-90k | Q16: =_xlfn.XMATCH(tbl_Clean[[#This Row],[Income Band]],{"$10k-30k","$40k-60k","$70k-90k","$100k+"}) -> 3 | R16: =IF(tbl_Clean[[#This Row],[Cars]]<=1,"0-1 Cars","2+ Cars") -> 2+ Cars | S16: =_xlfn.XMATCH(tbl_Clean[[#This Row],[Commute Distance]],{"0-1 Miles","1-2 Miles","2-5 Miles","5-10 Miles","10+ Miles"}) -> 5 | T16: =_xlfn.XMATCH(tbl_Clean[[#This Row],[Education]],{"Partial High School","High School","Partial College","Bachelors","Graduate Degree"}) -> 4 | U16: =IF(tbl_Clean[[#This Row],[Purchased Bike]]="Yes",1,0) -> 0
... A1004: 12121 | B1004: Single | C1004: Male | D1004: 60000 | E1004: 3 | F1004: High School | G1004: Professional | H1004: Yes | I1004: 2 | J1004: 10+ Miles | K1004: North America | L1004: 53 | M1004: Yes | N1004: {=_xlfn.IFS(tbl_Clean[[#This Row],[Age]]<=30,"25-30",tbl_Clean[[#This Row],[Age]]<=40,"31-40",tbl_Clean[[#This Row],[Age]]<=50,"41-50",tbl_Clean[[#This Row],[Age]]<=60,"51-60",TRUE,"61+")} -> 51-60 | O1004: =_xlfn.XMATCH(tbl_Clean[[#This Row],[Age Band]],{"25-30","31-40","41-50","51-60","61+"}) -> 4 | P1004: {=_xlfn.IFS(tbl_Clean[[#This Row],[Income]]<=30000,"$10k-30k",tbl_Clean[[#This Row],[Income]]<=60000,"$40k-60k",tbl_Clean[[#This Row],[Income]]<=90000,"$70k-90k",TRUE,"$100k+")} -> $40k-60k | Q1004: =_xlfn.XMATCH(tbl_Clean[[#This Row],[Income Band]],{"$10k-30k","$40k-60k","$70k-90k","$100k+"}) -> 2 | R1004: =IF(tbl_Clean[[#This Row],[Cars]]<=1,"0-1 Cars","2+ Cars") -> 2+ Cars | S1004: =_xlfn.XMATCH(tbl_Clean[[#This Row],[Commute Distance]],{"0-1 Miles","1-2 Miles","2-5 Miles","5-10 Miles","10+ Miles"}) -> 5 | T1004: =_xlfn.XMATCH(tbl_Clean[[#This Row],[Education]],{"Partial High School","High School","Partial College","Bachelors","Graduate Degree"}) -> 2 | U1004: =IF(tbl_Clean[[#This Row],[Purchased Bike]]="Yes",1,0) -> 1

Sheet Segment_Analysis
A1: Segment analysis: purchase rate by customer attribute
A2: Purpose: live purchase rate, lift vs the overall average and buyer share for every segment of every factor, ranked by how strongly each factor separates buyers.
A4: Total customers | B4: =ROWS(tbl_Clean[]) -> 1000 | C4: Total buyers | D4: =SUM(tbl_Clean[Purchased Flag]) -> 481 | E4: Overall purchase rate | F4: =D4/B4 -> 0.481
A6: Observations
A7: {=_xlfn.LET(_xlpm.seg,_xlfn.ANCHORARRAY(A34),_xlpm.rt,_xlfn.ANCHORARRAY(D34),_xlpm.hi,MAX(_xlpm.rt),_xlpm.lo,MIN(_xlpm.rt),"Highest-converting age band: "&_xlfn.XLOOKUP(_xlpm.hi,_xlpm.rt,_xlpm.seg)&" at "&TEXT(_xlpm.hi,"0.0%")&" ("&TEXT(_xlpm.hi/Baseline_Rate,"0.00")&"x the average); lowest: "&_xlfn.XLOOKUP(_xlpm.lo,_xlpm.rt,_xlpm.seg)&" at "&TEXT(_xlpm.lo,"0.0%")&" ("&TEXT(_xlpm.lo/Baseline_Rate,"0.00")&"x).")} -> Highest-converting age band: 31-40 at 61.1% (1.27x the average); lowest: 61+ at 30.0% (0.62x).
A8: {=_xlfn.LET(_xlpm.seg,_xlfn.ANCHORARRAY(A13),_xlpm.rt,_xlfn.ANCHORARRAY(D13),_xlpm.hi,MAX(_xlpm.rt),_xlpm.lo,MIN(_xlpm.rt),"Highest-converting car ownership group: "&_xlfn.XLOOKUP(_xlpm.hi,_xlpm.rt,_xlpm.seg)&" at "&TEXT(_xlpm.hi,"0.0%")&" ("&TEXT(_xlpm.hi/Baseline_Rate,"0.00")&"x the average); lowest: "&_xlfn.XLOOKUP(_xlpm.lo,_xlpm.rt,_xlpm.seg)&" at "&TEXT(_xlpm.lo,"0.0%")&" ("&TEXT(_xlpm.lo/Baseline_Rate,"0.00")&"x).")} -> Highest-converting car ownership group: 0-1 Cars at 58.9% (1.23x the average); lowest: 2+ Cars at 36.6% (0.76x).
A9: {=_xlfn.LET(_xlpm.seg,_xlfn.ANCHORARRAY(A26),_xlpm.rt,_xlfn.ANCHORARRAY(D26),_xlpm.hi,MAX(_xlpm.rt),_xlpm.lo,MIN(_xlpm.rt),"Highest-converting commute distance: "&_xlfn.XLOOKUP(_xlpm.hi,_xlpm.rt,_xlpm.seg)&" at "&TEXT(_xlpm.hi,"0.0%")&" ("&TEXT(_xlpm.hi/Baseline_Rate,"0.00")&"x the average); lowest: "&_xlfn.XLOOKUP(_xlpm.lo,_xlpm.rt,_xlpm.seg)&" at "&TEXT(_xlpm.lo,"0.0%")&" ("&TEXT(_xlpm.lo/Baseline_Rate,"0.00")&"x).")} -> Highest-converting commute distance: 2-5 Miles at 58.6% (1.22x the average); lowest: 10+ Miles at 29.7% (0.62x).
A11: Car Ownership | I11: Factor ranking (sorted by spread, highest first)
A12: Segment | B12: Customers | C12: Buyers | D12: Purchase Rate | E12: Lift vs Avg | F12: Share of All Buyers | G12: Sample flag | I12: Factor | J12: Highest segment | K12: Highest rate | L12: Lowest segment | M12: Lowest rate | N12: Spread (pp)
A13: {=_xlfn.LET(_xlpm.s,_xlfn.UNIQUE(tbl_Clean[Car Ownership]),_xlfn.SORTBY(_xlpm.s,COUNTIFS(tbl_Clean[Car Ownership],_xlpm.s,tbl_Clean[Purchased Flag],1)/COUNTIFS(tbl_Clean[Car Ownership],_xlpm.s),-1))} -> 0-1 Cars | B13: {=COUNTIFS(tbl_Clean[Car Ownership],_xlfn.ANCHORARRAY(A13))} -> 514 | C13: {=COUNTIFS(tbl_Clean[Car Ownership],_xlfn.ANCHORARRAY(A13),tbl_Clean[Purchased Flag],1)} -> 303 | D13: {=_xlfn.ANCHORARRAY(C13)/_xlfn.ANCHORARRAY(B13)} -> 0.58949416 | E13: {=_xlfn.ANCHORARRAY(D13)/Baseline_Rate} -> 1.2255596 | F13: {=_xlfn.ANCHORARRAY(C13)/Total_Buyers} -> 0.62993763 | G13: {=IF(_xlfn.ANCHORARRAY(B13)<100,"Small sample","")} | I13: {=_xlfn.SORTBY(I29:N40,N29:N40,-1)} -> Children | J13: 1 | K13: 0.5739645 | L13: 5 | M13: 0.22222222 | N13: 35.174227
A14: 2+ Cars | B14: 486 | C14: 178 | D14: 0.36625514 | E14: 0.76144521 | F14: 0.37006237 | I14: Age Band | J14: 31-40 | K14: 0.61075949 | L14: 61+ | M14: 0.3 | N14: 31.075949
I15: Education | J15: Bachelors | K15: 0.55228758 | L15: Partial High School | M15: 0.26315789 | N15: 28.912969
A16: Cars | I16: Commute Distance | J16: 2-5 Miles | K16: 0.58641975 | L16: 10+ Miles | M16: 0.2972973 | N16: 28.912246
A17: Segment | B17: Customers | C17: Buyers | D17: Purchase Rate | E17: Lift vs Avg | F17: Share of All Buyers | G17: Sample flag | I17: Cars | J17: 0 | K17: 0.61133603 | L17: 4 | M17: 0.3559322 | N17: 25.540383
A18: {=_xlfn._xlws.SORT(_xlfn.UNIQUE(tbl_Clean[Cars]))} -> 0 | B18: {=COUNTIFS(tbl_Clean[Cars],_xlfn.ANCHORARRAY(A18))} -> 247 | C18: {=COUNTIFS(tbl_Clean[Cars],_xlfn.ANCHORARRAY(A18),tbl_Clean[Purchased Flag],1)} -> 151 | D18: {=_xlfn.ANCHORARRAY(C18)/_xlfn.ANCHORARRAY(B18)} -> 0.61133603 | E18: {=_xlfn.ANCHORARRAY(D18)/Baseline_Rate} -> 1.2709689 | F18: {=_xlfn.ANCHORARRAY(C18)/Total_Buyers} -> 0.31392931 | G18: {=IF(_xlfn.ANCHORARRAY(B18)<100,"Small sample","")} | I18: Car Ownership | J18: 0-1 Cars | K18: 0.58949416 | L18: 2+ Cars | M18: 0.36625514 | N18: 22.323902
A19: 1 | B19: 267 | C19: 152 | D19: 0.56928839 | E19: 1.1835517 | F19: 0.31600832 | I19: Region | J19: Pacific | K19: 0.58854167 | L19: North America | M19: 0.43307087 | N19: 15.54708
A20: 2 | B20: 342 | C20: 124 | D20: 0.3625731 | E20: 0.75379023 | F20: 0.25779626 | I20: Income Band | J20: $40k-60k | K20: 0.53203343 | L20: $10k-30k | M20: 0.40070922 | N20: 13.132421
A21: 3 | B21: 85 | C21: 33 | D21: 0.38823529 | E21: 0.80714198 | F21: 0.068607069 | G21: Small sample | I21: Occupation | J21: Professional | K21: 0.54347826 | L21: Management | M21: 0.42196532 | N21: 12.151294
A22: 4 | B22: 59 | C22: 21 | D22: 0.3559322 | E22: 0.73998379 | F22: 0.043659044 | G22: Small sample | I22: Marital Status | J22: Single | K22: 0.54112554 | L22: Married | M22: 0.42936803 | N22: 11.175751
I23: Home Owner | J23: No | K23: 0.49211356 | L23: Yes | M23: 0.47584187 | N23: 1.6271691
A24: Commute Distance | I24: Gender | J24: Female | K24: 0.48875256 | L24: Male | M24: 0.47358121 | N24: 1.5171343
A25: Segment | B25: Customers | C25: Buyers | D25: Purchase Rate | E25: Lift vs Avg | F25: Share of All Buyers | G25: Sample flag
A26: {=_xlfn.LET(_xlpm.u,_xlfn.UNIQUE(_xlfn.HSTACK(tbl_Clean[Commute Distance],tbl_Clean[Commute Sort])),_xlfn.TAKE(_xlfn._xlws.SORT(_xlpm.u,2),,1))} -> 0-1 Miles | B26: {=COUNTIFS(tbl_Clean[Commute Distance],_xlfn.ANCHORARRAY(A26))} -> 366 | C26: {=COUNTIFS(tbl_Clean[Commute Distance],_xlfn.ANCHORARRAY(A26),tbl_Clean[Purchased Flag],1)} -> 200 | D26: {=_xlfn.ANCHORARRAY(C26)/_xlfn.ANCHORARRAY(B26)} -> 0.54644809 | E26: {=_xlfn.ANCHORARRAY(D26)/Baseline_Rate} -> 1.1360667 | F26: {=_xlfn.ANCHORARRAY(C26)/Total_Buyers} -> 0.41580042 | G26: {=IF(_xlfn.ANCHORARRAY(B26)<100,"Small sample","")}
A27: 1-2 Miles | B27: 169 | C27: 77 | D27: 0.4556213 | E27: 0.94723763 | F27: 0.16008316 | I27: Ranking workings (unsorted; feeds the factor ranking above)
A28: 2-5 Miles | B28: 162 | C28: 95 | D28: 0.58641975 | E28: 1.2191679 | F28: 0.1975052 | I28: Factor | J28: Highest segment | K28: Highest rate | L28: Lowest segment | M28: Lowest rate | N28: Spread (pp)
A29: 5-10 Miles | B29: 192 | C29: 76 | D29: 0.39583333 | E29: 0.82293832 | F29: 0.15800416 | I29: Car Ownership | J29: {=_xlfn.XLOOKUP(K29,_xlfn.ANCHORARRAY(D13),_xlfn.ANCHORARRAY(A13))} -> 0-1 Cars | K29: =MAX(_xlfn.ANCHORARRAY(D13)) -> 0.58949416 | L29: {=_xlfn.XLOOKUP(M29,_xlfn.ANCHORARRAY(D13),_xlfn.ANCHORARRAY(A13))} -> 2+ Cars | M29: =MIN(_xlfn.ANCHORARRAY(D13)) -> 0.36625514 | N29: =(K29-M29)*100 -> 22.323902
A30: 10+ Miles | B30: 111 | C30: 33 | D30: 0.2972973 | E30: 0.6180817 | F30: 0.068607069 | I30: Cars | J30: {=_xlfn.XLOOKUP(K30,_xlfn.ANCHORARRAY(D18),_xlfn.ANCHORARRAY(A18))} -> 0 | K30: =MAX(_xlfn.ANCHORARRAY(D18)) -> 0.61133603 | L30: {=_xlfn.XLOOKUP(M30,_xlfn.ANCHORARRAY(D18),_xlfn.ANCHORARRAY(A18))} -> 4 | M30: =MIN(_xlfn.ANCHORARRAY(D18)) -> 0.3559322 | N30: =(K30-M30)*100 -> 25.540383
I31: Commute Distance | J31: {=_xlfn.XLOOKUP(K31,_xlfn.ANCHORARRAY(D26),_xlfn.ANCHORARRAY(A26))} -> 2-5 Miles | K31: =MAX(_xlfn.ANCHORARRAY(D26)) -> 0.58641975 | L31: {=_xlfn.XLOOKUP(M31,_xlfn.ANCHORARRAY(D26),_xlfn.ANCHORARRAY(A26))} -> 10+ Miles | M31: =MIN(_xlfn.ANCHORARRAY(D26)) -> 0.2972973 | N31: =(K31-M31)*100 -> 28.912246
A32: Age Band | I32: Age Band | J32: {=_xlfn.XLOOKUP(K32,_xlfn.ANCHORARRAY(D34),_xlfn.ANCHORARRAY(A34))} -> 31-40 | K32: =MAX(_xlfn.ANCHORARRAY(D34)) -> 0.61075949 | L32: {=_xlfn.XLOOKUP(M32,_xlfn.ANCHORARRAY(D34),_xlfn.ANCHORARRAY(A34))} -> 61+ | M32: =MIN(_xlfn.ANCHORARRAY(D34)) -> 0.3 | N32: =(K32-M32)*100 -> 31.075949
A33: Segment | B33: Customers | C33: Buyers | D33: Purchase Rate | E33: Lift vs Avg | F33: Share of All Buyers | G33: Sample flag | I33: Children | J33: {=_xlfn.XLOOKUP(K33,_xlfn.ANCHORARRAY(D42),_xlfn.ANCHORARRAY(A42))} -> 1 | K33: =MAX(_xlfn.ANCHORARRAY(D42)) -> 0.5739645 | L33: {=_xlfn.XLOOKUP(M33,_xlfn.ANCHORARRAY(D42),_xlfn.ANCHORARRAY(A42))} -> 5 | M33: =MIN(_xlfn.ANCHORARRAY(D42)) -> 0.22222222 | N33: =(K33-M33)*100 -> 35.174227
A34: {=_xlfn.LET(_xlpm.u,_xlfn.UNIQUE(_xlfn.HSTACK(tbl_Clean[Age Band],tbl_Clean[Age Band Sort])),_xlfn.TAKE(_xlfn._xlws.SORT(_xlpm.u,2),,1))} -> 25-30 | B34: {=COUNTIFS(tbl_Clean[Age Band],_xlfn.ANCHORARRAY(A34))} -> 110 | C34: {=COUNTIFS(tbl_Clean[Age Band],_xlfn.ANCHORARRAY(A34),tbl_Clean[Purchased Flag],1)} -> 39 | D34: {=_xlfn.ANCHORARRAY(C34)/_xlfn.ANCHORARRAY(B34)} -> 0.35454545 | E34: {=_xlfn.ANCHORARRAY(D34)/Baseline_Rate} -> 0.73710074 | F34: {=_xlfn.ANCHORARRAY(C34)/Total_Buyers} -> 0.081081081 | G34: {=IF(_xlfn.ANCHORARRAY(B34)<100,"Small sample","")} | I34: Education | J34: {=_xlfn.XLOOKUP(K34,_xlfn.ANCHORARRAY(D51),_xlfn.ANCHORARRAY(A51))} -> Bachelors | K34: =MAX(_xlfn.ANCHORARRAY(D51)) -> 0.55228758 | L34: {=_xlfn.XLOOKUP(M34,_xlfn.ANCHORARRAY(D51),_xlfn.ANCHORARRAY(A51))} -> Partial High School | M34: =MIN(_xlfn.ANCHORARRAY(D51)) -> 0.26315789 | N34: =(K34-M34)*100 -> 28.912969
A35: 31-40 | B35: 316 | C35: 193 | D35: 0.61075949 | E35: 1.2697703 | F35: 0.4012474 | I35: Region | J35: {=_xlfn.XLOOKUP(K35,_xlfn.ANCHORARRAY(D59),_xlfn.ANCHORARRAY(A59))} -> Pacific | K35: =MAX(_xlfn.ANCHORARRAY(D59)) -> 0.58854167 | L35: {=_xlfn.XLOOKUP(M35,_xlfn.ANCHORARRAY(D59),_xlfn.ANCHORARRAY(A59))} -> North America | M35: =MIN(_xlfn.ANCHORARRAY(D59)) -> 0.43307087 | N35: =(K35-M35)*100 -> 15.54708
A36: 41-50 | B36: 298 | C36: 139 | D36: 0.46644295 | E36: 0.96973587 | F36: 0.28898129 | I36: Marital Status | J36: {=_xlfn.XLOOKUP(K36,_xlfn.ANCHORARRAY(D65),_xlfn.ANCHORARRAY(A65))} -> Single | K36: =MAX(_xlfn.ANCHORARRAY(D65)) -> 0.54112554 | L36: {=_xlfn.XLOOKUP(M36,_xlfn.ANCHORARRAY(D65),_xlfn.ANCHORARRAY(A65))} -> Married | M36: =MIN(_xlfn.ANCHORARRAY(D65)) -> 0.42936803 | N36: =(K36-M36)*100 -> 11.175751
A37: 51-60 | B37: 176 | C37: 80 | D37: 0.45454545 | E37: 0.94500095 | F37: 0.16632017 | I37: Income Band | J37: {=_xlfn.XLOOKUP(K37,_xlfn.ANCHORARRAY(D70),_xlfn.ANCHORARRAY(A70))} -> $40k-60k | K37: =MAX(_xlfn.ANCHORARRAY(D70)) -> 0.53203343 | L37: {=_xlfn.XLOOKUP(M37,_xlfn.ANCHORARRAY(D70),_xlfn.ANCHORARRAY(A70))} -> $10k-30k | M37: =MIN(_xlfn.ANCHORARRAY(D70)) -> 0.40070922 | N37: =(K37-M37)*100 -> 13.132421
A38: 61+ | B38: 100 | C38: 30 | D38: 0.3 | E38: 0.62370062 | F38: 0.062370062 | I38: Occupation | J38: {=_xlfn.XLOOKUP(K38,_xlfn.ANCHORARRAY(D77),_xlfn.ANCHORARRAY(A77))} -> Professional | K38: =MAX(_xlfn.ANCHORARRAY(D77)) -> 0.54347826 | L38: {=_xlfn.XLOOKUP(M38,_xlfn.ANCHORARRAY(D77),_xlfn.ANCHORARRAY(A77))} -> Management | M38: =MIN(_xlfn.ANCHORARRAY(D77)) -> 0.42196532 | N38: =(K38-M38)*100 -> 12.151294
I39: Home Owner | J39: {=_xlfn.XLOOKUP(K39,_xlfn.ANCHORARRAY(D85),_xlfn.ANCHORARRAY(A85))} -> No | K39: =MAX(_xlfn.ANCHORARRAY(D85)) -> 0.49211356 | L39: {=_xlfn.XLOOKUP(M39,_xlfn.ANCHORARRAY(D85),_xlfn.ANCHORARRAY(A85))} -> Yes | M39: =MIN(_xlfn.ANCHORARRAY(D85)) -> 0.47584187 | N39: =(K39-M39)*100 -> 1.6271691
A40: Children | I40: Gender | J40: {=_xlfn.XLOOKUP(K40,_xlfn.ANCHORARRAY(D90),_xlfn.ANCHORARRAY(A90))} -> Female | K40: =MAX(_xlfn.ANCHORARRAY(D90)) -> 0.48875256 | L40: {=_xlfn.XLOOKUP(M40,_xlfn.ANCHORARRAY(D90),_xlfn.ANCHORARRAY(A90))} -> Male | M40: =MIN(_xlfn.ANCHORARRAY(D90)) -> 0.47358121 | N40: =(K40-M40)*100 -> 1.5171343
A41: Segment | B41: Customers | C41: Buyers | D41: Purchase Rate | E41: Lift vs Avg | F41: Share of All Buyers | G41: Sample flag
A42: {=_xlfn._xlws.SORT(_xlfn.UNIQUE(tbl_Clean[Children]))} -> 0 | B42: {=COUNTIFS(tbl_Clean[Children],_xlfn.ANCHORARRAY(A42))} -> 281 | C42: {=COUNTIFS(tbl_Clean[Children],_xlfn.ANCHORARRAY(A42),tbl_Clean[Purchased Flag],1)} -> 142 | D42: {=_xlfn.ANCHORARRAY(C42)/_xlfn.ANCHORARRAY(B42)} -> 0.50533808 | E42: {=_xlfn.ANCHORARRAY(D42)/Baseline_Rate} -> 1.0505989 | F42: {=_xlfn.ANCHORARRAY(C42)/Total_Buyers} -> 0.2952183 | G42: {=IF(_xlfn.ANCHORARRAY(B42)<100,"Small sample","")}
A43: 1 | B43: 169 | C43: 97 | D43: 0.5739645 | E43: 1.1932734 | F43: 0.2016632
...

Sheet Significance_Tests
A1: Significance tests: which factors really matter?
A2: Purpose: chi-square tests of independence for each factor vs bike purchase, with effect size (Cramér's V), to separate real drivers from chance.
A4: How to read this
A5: • Chi-square test: compares actual buyers per segment with the number expected if the factor had no effect.
A6: • p-value < 0.05 = the difference is statistically significant (unlikely to be chance).
A7: • Cramér's V = strength of the relationship: <0.10 Negligible, 0.10–0.19 Small, 0.20–0.29 Moderate, ≥0.30 Strong.
A9: Results summary (sorted by Cramér's V, strongest first)
A10: Factor | B10: Chi-square | C10: df | D10: p-value | E10: Cramér's V | F10: Strength | G10: Significant? | H10: Valid (min expected ≥5) | I10: Plain-English Verdict
A11: {=INDEX(_xlfn.SORTBY(tbl_SigWorkings[Factor],tbl_SigWorkings[Cramér''s V],-1),ROW()-ROW(tbl_Significance[#Headers]))} -> Cars | B11: =_xlfn.XLOOKUP(tbl_Significance[[#This Row],[Factor]],tbl_SigWorkings[Factor],tbl_SigWorkings[Chi-square]) -> 50.985549 | C11: =_xlfn.XLOOKUP(tbl_Significance[[#This Row],[Factor]],tbl_SigWorkings[Factor],tbl_SigWorkings[df]) -> 4 | D11: =_xlfn.XLOOKUP(tbl_Significance[[#This Row],[Factor]],tbl_SigWorkings[Factor],tbl_SigWorkings[p-value]) -> 2.2477924e-10 | E11: =_xlfn.XLOOKUP(tbl_Significance[[#This Row],[Factor]],tbl_SigWorkings[Factor],tbl_SigWorkings[Cramér''s V]) -> 0.2257998 | F11: {=_xlfn.IFS(tbl_Significance[[#This Row],[Cramér''s V]]<0.1,"Negligible",tbl_Significance[[#This Row],[Cramér''s V]]<0.2,"Small",tbl_Significance[[#This Row],[Cramér''s V]]<0.3,"Moderate",TRUE,"Strong")} -> Moderate | G11: =IF(tbl_Significance[[#This Row],[p-value]]<0.05,"Yes","No") -> Yes | H11: =IF(_xlfn.XLOOKUP(tbl_Significance[[#This Row],[Factor]],tbl_SigWorkings[Factor],tbl_SigWorkings[Min Expected])>=5,"Yes","No") -> Yes | I11: =IF(tbl_Significance[[#This Row],[Significant?]]="Yes","Matters – "&tbl_Significance[[#This Row],[Strength]]&" effect","No evidence it matters")&IF(tbl_Significance[[#This Row],[Valid (min expected ≥5)]]="No"," (caution: small expected counts)","") -> Matters – Moderate effect
A12: {=INDEX(_xlfn.SORTBY(tbl_SigWorkings[Factor],tbl_SigWorkings[Cramér''s V],-1),ROW()-ROW(tbl_Significance[#Headers]))} -> Car Ownership | B12: =_xlfn.XLOOKUP(tbl_Significance[[#This Row],[Factor]],tbl_SigWorkings[Factor],tbl_SigWorkings[Chi-square]) -> 49.868599 | C12: =_xlfn.XLOOKUP(tbl_Significance[[#This Row],[Factor]],tbl_SigWorkings[Factor],tbl_SigWorkings[df]) -> 1 | D12: =_xlfn.XLOOKUP(tbl_Significance[[#This Row],[Factor]],tbl_SigWorkings[Factor],tbl_SigWorkings[p-value]) -> 1.6439466e-12 | E12: =_xlfn.XLOOKUP(tbl_Significance[[#This Row],[Factor]],tbl_SigWorkings[Factor],tbl_SigWorkings[Cramér''s V]) -> 0.22331278 | F12: {=_xlfn.IFS(tbl_Significance[[#This Row],[Cramér''s V]]<0.1,"Negligible",tbl_Significance[[#This Row],[Cramér''s V]]<0.2,"Small",tbl_Significance[[#This Row],[Cramér''s V]]<0.3,"Moderate",TRUE,"Strong")} -> Moderate | G12: =IF(tbl_Significance[[#This Row],[p-value]]<0.05,"Yes","No") -> Yes | H12: =IF(_xlfn.XLOOKUP(tbl_Significance[[#This Row],[Factor]],tbl_SigWorkings[Factor],tbl_SigWorkings[Min Expected])>=5,"Yes","No") -> Yes | I12: =IF(tbl_Significance[[#This Row],[Significant?]]="Yes","Matters – "&tbl_Significance[[#This Row],[Strength]]&" effect","No evidence it matters")&IF(tbl_Significance[[#This Row],[Valid (min expected ≥5)]]="No"," (caution: small expected counts)","") -> Matters – Moderate effect
A13: {=INDEX(_xlfn.SORTBY(tbl_SigWorkings[Factor],tbl_SigWorkings[Cramér''s V],-1),ROW()-ROW(tbl_Significance[#Headers]))} -> Age Band | B13: =_xlfn.XLOOKUP(tbl_Significance[[#This Row],[Factor]],tbl_SigWorkings[Factor],tbl_SigWorkings[Chi-square]) -> 42.229226 | C13: =_xlfn.XLOOKUP(tbl_Significance[[#This Row],[Factor]],tbl_SigWorkings[Factor],tbl_SigWorkings[df]) -> 4 | D13: =_xlfn.XLOOKUP(tbl_Significance[[#This Row],[Factor]],tbl_SigWorkings[Factor],tbl_SigWorkings[p-value]) -> 1.4952691e-08 | E13: =_xlfn.XLOOKUP(tbl_Significance[[#This Row],[Factor]],tbl_SigWorkings[Factor],tbl_SigWorkings[Cramér''s V]) -> 0.20549751 | F13: {=_xlfn.IFS(tbl_Significance[[#This Row],[Cramér''s V]]<0.1,"Negligible",tbl_Significance[[#This Row],[Cramér''s V]]<0.2,"Small",tbl_Significance[[#This Row],[Cramér''s V]]<0.3,"Moderate",TRUE,"Strong")} -> Moderate | G13: =IF(tbl_Significance[[#This Row],[p-value]]<0.05,"Yes","No") -> Yes | H13: =IF(_xlfn.XLOOKUP(tbl_Significance[[#This Row],[Factor]],tbl_SigWorkings[Factor],tbl_SigWorkings[Min Expected])>=5,"Yes","No") -> Yes | I13: =IF(tbl_Significance[[#This Row],[Significant?]]="Yes","Matters – "&tbl_Significance[[#This Row],[Strength]]&" effect","No evidence it matters")&IF(tbl_Significance[[#This Row],[Valid (min expected ≥5)]]="No"," (caution: small expected counts)","") -> Matters – Moderate effect
A14: {=INDEX(_xlfn.SORTBY(tbl_SigWorkings[Factor],tbl_SigWorkings[Cramér''s V],-1),ROW()-ROW(tbl_Significance[#Headers]))} -> Commute Distance | B14: =_xlfn.XLOOKUP(tbl_Significance[[#This Row],[Factor]],tbl_SigWorkings[Factor],tbl_SigWorkings[Chi-square]) -> 34.511749 | C14: =_xlfn.XLOOKUP(tbl_Significance[[#This Row],[Factor]],tbl_SigWorkings[Factor],tbl_SigWorkings[df]) -> 4 | D14: =_xlfn.XLOOKUP(tbl_Significance[[#This Row],[Factor]],tbl_SigWorkings[Factor],tbl_SigWorkings[p-value]) -> 5.8515598e-07 | E14: =_xlfn.XLOOKUP(tbl_Significance[[#This Row],[Factor]],tbl_SigWorkings[Factor],tbl_SigWorkings[Cramér''s V]) -> 0.18577338 | F14: {=_xlfn.IFS(tbl_Significance[[#This Row],[Cramér''s V]]<0.1,"Negligible",tbl_Significance[[#This Row],[Cramér''s V]]<0.2,"Small",tbl_Significance[[#This Row],[Cramér''s V]]<0.3,"Moderate",TRUE,"Strong")} -> Small | G14: =IF(tbl_Significance[[#This Row],[p-value]]<0.05,"Yes","No") -> Yes | H14: =IF(_xlfn.XLOOKUP(tbl_Significance[[#This Row],[Factor]],tbl_SigWorkings[Factor],tbl_SigWorkings[Min Expected])>=5,"Yes","No") -> Yes | I14: =IF(tbl_Significance[[#This Row],[Significant?]]="Yes","Matters – "&tbl_Significance[[#This Row],[Strength]]&" effect","No evidence it matters")&IF(tbl_Significance[[#This Row],[Valid (min expected ≥5)]]="No"," (caution: small expected counts)","") -> Matters – Small effect
A15: {=INDEX(_xlfn.SORTBY(tbl_SigWorkings[Factor],tbl_SigWorkings[Cramér''s V],-1),ROW()-ROW(tbl_Significance[#Headers]))} -> Children | B15: =_xlfn.XLOOKUP(tbl_Significance[[#This Row],[Factor]],tbl_SigWorkings[Factor],tbl_SigWorkings[Chi-square]) -> 32.055151 | C15: =_xlfn.XLOOKUP(tbl_Significance[[#This Row],[Factor]],tbl_SigWorkings[Factor],tbl_SigWorkings[df]) -> 5 | D15: =_xlfn.XLOOKUP(tbl_Significance[[#This Row],[Factor]],tbl_SigWorkings[Factor],tbl_SigWorkings[p-value]) -> 5.7937088e-06 | E15: =_xlfn.XLOOKUP(tbl_Significance[[#This Row],[Factor]],tbl_SigWorkings[Factor],tbl_SigWorkings[Cramér''s V]) -> 0.17903952 | F15: {=_xlfn.IFS(tbl_Significance[[#This Row],[Cramér''s V]]<0.1,"Negligible",tbl_Significance[[#This Row],[Cramér''s V]]<0.2,"Small",tbl_Significance[[#This Row],[Cramér''s V]]<0.3,"Moderate",TRUE,"Strong")} -> Small | G15: =IF(tbl_Significance[[#This Row],[p-value]]<0.05,"Yes","No") -> Yes | H15: =IF(_xlfn.XLOOKUP(tbl_Significance[[#This Row],[Factor]],tbl_SigWorkings[Factor],tbl_SigWorkings[Min Expected])>=5,"Yes","No") -> Yes | I15: =IF(tbl_Significance[[#This Row],[Significant?]]="Yes","Matters – "&tbl_Significance[[#This Row],[Strength]]&" effect","No evidence it matters")&IF(tbl_Significance[[#This Row],[Valid (min expected ≥5)]]="No"," (caution: small expected counts)","") -> Matters – Small effect
A16: {=INDEX(_xlfn.SORTBY(tbl_SigWorkings[Factor],tbl_SigWorkings[Cramér''s V],-1),ROW()-ROW(tbl_Significance[#Headers]))} -> Education | B16: =_xlfn.XLOOKUP(tbl_Significance[[#This Row],[Factor]],tbl_SigWorkings[Factor],tbl_SigWorkings[Chi-square]) -> 25.332685 | C16: =_xlfn.XLOOKUP(tbl_Significance[[#This Row],[Factor]],tbl_SigWorkings[Factor],tbl_SigWorkings[df]) -> 4 | D16: =_xlfn.XLOOKUP(tbl_Significance[[#This Row],[Factor]],tbl_SigWorkings[Factor],tbl_SigWorkings[p-value]) -> 4.3125063e-05 | E16: =_xlfn.XLOOKUP(tbl_Significance[[#This Row],[Factor]],tbl_SigWorkings[Factor],tbl_SigWorkings[Cramér''s V]) -> 0.15916245 | F16: {=_xlfn.IFS(tbl_Significance[[#This Row],[Cramér''s V]]<0.1,"Negligible",tbl_Significance[[#This Row],[Cramér''s V]]<0.2,"Small",tbl_Significance[[#This Row],[Cramér''s V]]<0.3,"Moderate",TRUE,"Strong")} -> Small | G16: =IF(tbl_Significance[[#This Row],[p-value]]<0.05,"Yes","No") -> Yes | H16: =IF(_xlfn.XLOOKUP(tbl_Significance[[#This Row],[Factor]],tbl_SigWorkings[Factor],tbl_SigWorkings[Min Expected])>=5,"Yes","No") -> Yes | I16: =IF(tbl_Significance[[#This Row],[Significant?]]="Yes","Matters – "&tbl_Significance[[#This Row],[Strength]]&" effect","No evidence it matters")&IF(tbl_Significance[[#This Row],[Valid (min expected ≥5)]]="No"," (caution: small expected counts)","") -> Matters – Small effect
